Workbook

Sheet Summary
B2: 50-58 JERSEY STREET
B3: Newark, New Jersey | Mixed-Use Residential Development
B4: Pro Forma Summary Dashboard
B6: PROJECT OVERVIEW
B7: Total Residential Units | C7: ='Inputs'!C12
B8: Market Rate Units | C8: ='Inputs'!C13 | E8: RETURNS SUMMARY | H8: REVENUE SUMMARY (STABILIZED)
B9: Affordable Units | C9: ='Inputs'!C14 | E9: Stabilized NOI (Year 3) | F9: ='Operating'!N29 | H9: Market Rate Rental Income | I9: ='Operating'!N8
B10: Building GSF | C10: ='Inputs'!C8 | E10: Stabilized Yield on Cost | F10: ='Operating'!N30 | H10: Affordable Rental Income | I10: ='Operating'!N9
B11: Residential NSF | C11: ='Inputs'!C9 | E11: Unlevered IRR | F11: ='Waterfall'!C58 | H11: Retail Income | I11: ='Operating'!N10
B12: Retail SF | C12: ='Inputs'!C10 | E12: Levered IRR (Project) | F12: ='Waterfall'!C59 | H12: Parking Income | I12: ='Operating'!N11
B13: Parking Spaces | C13: ='Inputs'!C16 | E13: Equity Multiple | F13: ='Waterfall'!C60 | H13: Other Income | I13: ='Operating'!N12
B14: Number of Floors | C14: ='Inputs'!C7 | E14: Cash-on-Cash (Stabilized) | F14: ='Waterfall'!C61 | H14: Gross Potential Revenue | I14: ='Operating'!N13
B15: Site Area (Acres) | C15: ='Inputs'!C6 | E15: Sponsor IRR | F15: ='Waterfall'!C63 | H15: Less: Vacancy & Credit Loss | I15: ='Operating'!N15
E16: Sponsor Equity Multiple | F16: ='Waterfall'!C64 | H16: Effective Gross Income | I16: ='Operating'!N16
B17: DEVELOPMENT BUDGET | E17: LP IRR | F17: ='Waterfall'!C65 | H17: Total Operating Expenses | I17: ='Operating'!N27
B18: Land Acquisition | C18: ='Dev Budget'!D8 | E18: LP Equity Multiple | F18: ='Waterfall'!C66 | H18: Net Operating Income | I18: ='Operating'!N29
B19: Hard Costs | C19: ='Dev Budget'!D18
B20: Soft Costs | C20: ='Dev Budget'!D30 | E20: FINANCING STRUCTURE | H20: KEY METRICS
B21: Financing Costs | C21: ='Dev Budget'!D40 | E21: Total Equity Required | F21: ='Waterfall'!C10 | H21: Avg Market Rent / Unit / Mo | I21: ='Unit Mix'!H29
B22: Developer Fee | C22: ='Dev Budget'!D42 | E22: Sponsor Equity (GP) | F22: ='Waterfall'!C12 | H22: Avg Market Rent / SF / Mo | I22: ='Unit Mix'!I29
B23: Total Development Cost | C23: ='Dev Budget'!D44 | E23: LP Equity | F23: ='Waterfall'!C13 | H23: Avg Affordable Rent / Unit / Mo | I23: ='Affordable'!G22
B24: TDC per Unit | C24: ='Dev Budget'!E44 | E24: Permanent Loan Amount | F24: ='Waterfall'!C15 | H24: OpEx per Unit | I24: ='Operating'!O27
B25: TDC per GSF | C25: ='Dev Budget'!F44 | E25: Loan-to-Value | F25: ='Inputs'!C57 | H25: OpEx Ratio | I25: ='Operating'!P27
E26: DSCR | F26: ='Operating'!N31 | H26: Exit Cap Rate | I26: ='Inputs'!C63
E27: Aspire Tax Credits (Total) | F27: ='Aspire'!C30 | H27: Estimated Exit Value (Yr 10) | I27: ='Waterfall'!C50
E28: Aspire Credits (Net Proceeds) | F28: ='Aspire'!C33

Sheet Inputs
B2: INPUTS & ASSUMPTIONS
B3: Blue bold cells are user-adjustable inputs. All other values are calculated.
B5: SITE & BUILDING DATA
B6: Project Name | C6: 50-58 Jersey Street | E6: User input: Project identifier
B7: Site Area (Acres) | C7: 1.17
B8: Number of Floors | C8: 25 | E8: Excludes amenity roof level
B9: Building GSF | C9: 763489
B10: Residential NSF | C10: 525338
B11: Retail Area (SF) | C11: 3474
B12: Amenity Area (SF) | C12: 54813
B13: Total Residential Units | C13: 716 | E13: =C13+C14
B14: Market Rate Units | C14: 573
B15: Affordable Units | C15: 143 | E15: ~20% of total
B16: Open Space (SF) | C16: 6534
B17: Parking Spaces | C17: 178 | E17: 0.25 spaces/unit ratio
B18: Green Wall (SF) | C18: 1500
B19: Average Unit Size (NSF) | C19: 734 | E19: Blended average
B21: MARKET RENT ASSUMPTIONS (Monthly)
B22: Rents based on Newark new construction comps (Downtown/Broad St corridor)
B23: Studio Rent (Market) | C23: 1950 | E23: 475 avg SF | $4.11/SF
B24: 1BR Rent (Market) | C24: 2400 | E24: 675 avg SF | $3.56/SF
B25: 1BR+Den Rent (Market) | C25: 2700 | E25: 800 avg SF | $3.38/SF
B26: 2BR Rent (Market) | C26: 3100 | E26: 1,000 avg SF | $3.10/SF
B27: 3BR Rent (Market) | C27: 3800 | E27: 1,200 avg SF | $3.17/SF
B29: AFFORDABLE RENT ASSUMPTIONS (Monthly, 60% AMI)
B30: Based on Essex County HUD FMR limits, 60% AMI. Adjust AMI level on Affordable tab.
B31: Studio Rent (Affordable) | C31: 1341 | E31: 60% AMI, Essex County
B32: 1BR Rent (Affordable) | C32: 1437 | E32: 60% AMI, Essex County
B33: 2BR Rent (Affordable) | C33: 1723 | E33: 60% AMI, Essex County
B34: 3BR Rent (Affordable) | C34: 1991 | E34: 60% AMI, Essex County
B36: OTHER REVENUE ASSUMPTIONS
B37: Retail Rent ($/SF/Year NNN) | C37: 28 | E37: Downtown Newark secondary location
B38: Parking Revenue ($/Space/Month) | C38: 175 | E38: Covered structured parking
B39: Other Income ($/Unit/Month) | C39: 50 | E39: Laundry, storage, fees, pets
B40: Vacancy & Credit Loss (%) | C40: 0.05 | E40: 5% stabilized; higher during lease-up
B41: Annual Rent Growth (Market) | C41: 0.025 | E41: 2.5% annual escalation
B42: Annual Rent Growth (Affordable) | C42: 0.02 | E42: 2.0% per HUD adjustments
B43: Retail Rent Growth | C43: 0.02 | E43: 2.0% annual escalation
B44: Parking Revenue Growth | C44: 0.02 | E44: 2.0% annual escalation
B46: OPERATING EXPENSE ASSUMPTIONS (Per Unit/Year)
...

Sheet Building Data
B2: BUILDING DATA - FLOOR-BY-FLOOR BREAKDOWN
B4: Floor | C4: Total GSF | D4: Parking GSF | E4: Garage Spaces | F4: Services | G4: Retail GSF | H4: Mechanical | I4: Outdoor Amenity | J4: Lobby/Amenity GSF | K4: Residential GSF | L4: Net Residential | M4: Studios | N4: 1BR | O4: 1BR+D | P4: 2BR
B5: Ground Floor | C5: 34787 | D5: 11164 | E5: 9 | F5: 1948 | G5: 3474 | H5: 3638 | I5: 0 | J5: 14513 | K5: 0 | L5: 0 | M5: 0 | N5: 0 | O5: 0 | P5: 0
B6: 2nd Floor | C6: 40569 | D6: 40569 | E6: 89 | F6: 0 | G6: 0 | H6: 0 | I6: 0 | J6: 0 | K6: 0 | L6: 0 | M6: 0 | N6: 0 | O6: 0 | P6: 0
B7: 2.5 Floor | C7: 29711 | D7: 29711 | E7: 80 | F7: 0 | G7: 0 | H7: 0 | I7: 0 | J7: 0 | K7: 0 | L7: 0 | M7: 0 | N7: 0 | O7: 0 | P7: 0
B8: 3rd Floor | C8: 30535 | D8: 0 | E8: 0 | F8: 0 | G8: 0 | H8: 0 | I8: 9421 | J8: 30578 | K8: 0 | L8: 0 | M8: 0 | N8: 0 | O8: 0 | P8: 0
B9: 4th Floor | C9: 28342 | D9: 0 | E9: 0 | F9: 0 | G9: 0 | H9: 0 | I9: 0 | J9: 0 | K9: 28342 | L9: 24305 | M9: 7 | N9: 4 | O9: 12 | P9: 3
B10: 5th Floor | C10: 28342 | D10: 0 | E10: 0 | F10: 0 | G10: 0 | H10: 0 | I10: 0 | J10: 0 | K10: 28342 | L10: 24305 | M10: 7 | N10: 4 | O10: 12 | P10: 3
B11: 6th Floor | C11: 28342 | D11: 0 | E11: 0 | F11: 0 | G11: 0 | H11: 0 | I11: 0 | J11: 0 | K11: 28342 | L11: 24305 | M11: 7 | N11: 4 | O11: 12 | P11: 3
B12: 7th Floor | C12: 28342 | D12: 0 | E12: 0 | F12: 0 | G12: 0 | H12: 0 | I12: 0 | J12: 0 | K12: 28342 | L12: 24305 | M12: 7 | N12: 4 | O12: 12 | P12: 3
B13: 8th Floor | C13: 28342 | D13: 0 | E13: 0 | F13: 0 | G13: 0 | H13: 0 | I13: 0 | J13: 0 | K13: 28342 | L13: 24305 | M13: 7 | N13: 4 | O13: 12 | P13: 3
B14: 9th Floor | C14: 28342 | D14: 0 | E14: 0 | F14: 0 | G14: 0 | H14: 0 | I14: 0 | J14: 0 | K14: 28342 | L14: 24305 | M14: 7 | N14: 4 | O14: 12 | P14: 3
B15: 10th Floor | C15: 27745 | D15: 0 | E15: 0 | F15: 0 | G15: 0 | H15: 0 | I15: 0 | J15: 0 | K15: 27745 | L15: 23723 | M15: 6 | N15: 2 | O15: 13 | P15: 2
B16: 11th Floor | C16: 27745 | D16: 0 | E16: 0 | F16: 0 | G16: 0 | H16: 0 | I16: 0 | J16: 0 | K16: 27745 | L16: 23723 | M16: 8 | N16: 0 | O16: 13 | P16: 2
... B31: Amenity Roof | C31: 13922 | D31: 0 | E31: 0 | F31: 0 | G31: 0 | H31: 0 | I31: 4200 | J31: 9722 | K31: 0 | L31: 0 | M31: 0 | N31: 0 | O31: 0 | P31: 0
B32: TOTALS | C32: 763489 | D32: 81444 | E32: 178 | F32: 1948 | G32: 3474 | H32: 3638 | I32: 13621 | J32: 54813 | L32: 525338
B35: SITE NOTES
B36: Site Area | C36: 51,093 SF (1.17 Acres)
B37: FAR | C37: 14.94
B38: Density | C38: 610 Units/Acre
B39: Parking Ratio | C39: 0.25 Spaces/Unit
B40: EV Spaces Required | C40: 27 (15% of 178)
B41: Open Space | C41: 6,534 SF (13%)
B42: Amenity % | C42: 7% of Building

Sheet Unit Mix
B2: MARKET RATE UNIT MIX
B4: Unit Type | C4: Units | D4: % of Total | E4: Avg SF | F4: Total NSF | G4: Monthly Rent | H4: Annual Rent/Unit | I4: Rent/SF/Mo | J4: Annual Revenue
B5: Studio | C5: 165 | D5: 0.28795812 | E5: 475 | F5: 78375 | G5: ='Inputs'!C22 | H5: 23400 | I5: 4.1052632 | J5: 3861000
B6: 1BR | C6: 280 | D6: 0.4886562 | E6: 675 | F6: 189000 | G6: ='Inputs'!C23 | H6: 28800 | I6: 3.5555556 | J6: 8064000
B7: 1BR + Den | C7: 50 | D7: 0.087260035 | E7: 800 | F7: 40000 | G7: ='Inputs'!C24 | H7: 32400 | I7: 3.375 | J7: 1620000
B8: 2BR | C8: 78 | D8: 0.13612565 | E8: 1000 | F8: 78000 | G8: ='Inputs'!C25 | H8: 37200 | I8: 3.1 | J8: 2901600
B9: MARKET RATE TOTAL | C9: 573 | D9: 1 | E9: 673 | F9: 385375 | G9: 2392 | H9: 28703 | I9: 3.5564061 | J9: 16446600
B12: COMBINED UNIT SUMMARY
B14: Category | C14: Units | D14: % of Total | E14: Avg SF | F14: Monthly Rent | G14: Annual Revenue
B15: Market Rate | C15: 573 | D15: 0.80027933 | E15: 673 | F15: 2392 | G15: 16446600
B16: Affordable | C16: 143 | D16: 0.19972067 | E16: 810 | F16: 1700 | G16: 2916996
B17: TOTAL / BLENDED | C17: 716 | D17: 1 | F17: 2254 | G17: 19363596

Sheet Affordable
B2: AFFORDABLE UNIT CALCULATIONS
B3: 20% affordable set-aside per NJ Aspire / Newark PILOT requirements
B5: AMI LEVEL SETTINGS
B6: Essex County Area Median Income (4-person) | C6: 107000 | E6: 2025 HUD AMI for Essex County, NJ
B7: Target AMI Level | C7: 0.6 | E7: Adjust: 30%, 50%, 60%, or 80% AMI
B9: RENT LIMITS BY AMI LEVEL (Monthly, Essex County)
B10: Unit Type | C10: 30% AMI | D10: 50% AMI | E10: 60% AMI | F10: 80% AMI | G10: Selected AMI
B11: Studio | C11: 670 | D11: 1118 | E11: 1341 | F11: 1788 | G11: 1341
B12: 1BR | C12: 718 | D12: 1198 | E12: 1437 | F12: 1916 | G12: 1437
B13: 2BR | C13: 861 | D13: 1436 | E13: 1723 | F13: 2298 | G13: 1723
B14: 3BR | C14: 995 | D14: 1659 | E14: 1991 | F14: 2655 | G14: 1991
B16: AFFORDABLE UNIT MIX
B17: Unit Type | C17: Units | D17: % of Aff. | E17: Avg SF | F17: Monthly Rent | G17: Annual Rent/Unit | H17: Annual Revenue
B18: Studio | C18: 29 | D18: 0.2027972 | E18: 475 | F18: 1341 | G18: 16092 | H18: 466668
B19: 2BR | C19: 85 | D19: 0.59440559 | E19: 1000 | F19: 1723 | G19: 20676 | H19: 1757460
B20: 3BR | C20: 29 | D20: 0.2027972 | E20: 1200 | F20: 1991 | G20: 23892 | H20: 692868
B21: AFFORDABLE TOTAL | C21: 143 | D21: 1 | G21: 1700 | H21: 2916996
B23: AFFORDABLE HOUSING COMPLIANCE
B24: Total Units | C24: 716
B25: Affordable Units | C25: 143
B26: Affordable % | C26: 20.0%
B27: Minimum Required (%) | C27: 20.0%
B28: Compliance Status | C28: COMPLIANT
B29: Affordability Term (Years) | C29: 30
B30: Rent Discount vs Market | C30: ~35-45%

Sheet Dev Budget
B2: DEVELOPMENT BUDGET
B3: All cost inputs are adjustable. Per-unit and per-SF metrics auto-calculate.
B5: # | C5: Line Item | D5: Total Cost | E5: $/Unit | F5: $/GSF | G5: % of TDC | H5: Notes
B6: LAND ACQUISITION
B7: 1 | C7: Land / Site Acquisition | D7: 25000000 | E7: 34916 | F7: 32.74 | G7: 0.061804848 | H7: Estimated acquisition cost
B9: HARD COSTS
B10: 2 | C10: Vertical Construction | D10: 248133925 | E10: 346556 | F10: 325 | H10: Base hard cost at $325/GSF (incl. structure)
B11: 3 | C11: Site Work & Infrastructure | D11: 9925357 | E11: 13862 | F11: 13 | H11: ~4% of base hard
B12: 4 | C12: Amenity Build-Out (Premium) | D12: 4110975 | E12: 5742 | F12: 5.38 | H12: $75/SF amenity premium above base
B13: 5 | C13: Retail Shell (Premium) | D13: 173700 | E13: 243 | F13: 0.23 | H13: $50/SF retail premium above base
B14: 6 | C14: Green Wall / Sustainability | D14: 300000 | E14: 419 | F14: 0.39 | H14: $200/SF green wall
B15: 7 | C15: FF&E (Common Areas) | D15: 2500000 | E15: 3492 | F15: 3.27 | H15: Lobby, amenity furnishings
B16: 8 | C16: Signage & Wayfinding | D16: 350000 | E16: 489 | F16: 0.46
C17: Hard Cost Contingency (7.5%) | D17: 19912047
C18: TOTAL HARD COSTS | D18: 285406004 | E18: 398612 | F18: 373.82
B20: SOFT COSTS
B21: 10 | C21: Architecture & Engineering | D21: 16128705 | E21: 22526 | F21: 21.12 | H21: 6.5% of base hard costs
B22: 11 | C22: Legal & Accounting | D22: 2977607 | E22: 4159 | F22: 3.9 | H22: 1.2% of hard costs
B23: 12 | C23: Permits & Impact Fees | D23: 4962678 | E23: 6931 | F23: 6.5 | H23: 2% of hard costs
B24: 13 | C24: Environmental / Testing | D24: 1985071 | E24: 2772 | F24: 2.6 | H24: 0.8% of hard costs
B25: 14 | C25: Title & Insurance (Construction) | D25: 2977607 | E25: 4159 | F25: 3.9 | H25: 1.2% of hard costs
B26: 15 | C26: Marketing / Pre-Leasing | D26: 1800000 | E26: 2514 | F26: 2.36 | H26: Branding, website, broker fees
B27: 16 | C27: Real Estate Taxes (During Const.) | D27: 2750000 | E27: 3841 | F27: 3.6 | H27: Est. ~2.75 yrs at 4%
B28: 17 | C28: Utility Connections | D28: 1200000 | E28: 1676 | F28: 1.57
C29: Soft Cost Contingency (10%) | D29: 3478167
C30: TOTAL SOFT COSTS | D30: 38259835 | E30: 53436 | F30: 50.11
B32: FINANCING COSTS
B33: 18 | C33: Construction Loan Interest | D33: 27686247 | E33: 38668 | H33: 7.5% on avg 55% drawn, 33 months
B34: 19 | C34: Construction Loan Origination | D34: 2440661 | E34: 3409 | H34: 1% of loan amount
B35: 20 | C35: Permanent Loan Origination | D35: 1220330 | E35: 1704 | H35: 0.5% est. perm loan fee
B36: 21 | C36: Other Financing Costs | D36: 500000 | E36: 698 | H36: Appraisals, rate locks, etc.
C37: TOTAL FINANCING COSTS | D37: 31847238
B39: 22 | C39: Developer Fee (4% of TDC) | D39: 15220523 | E39: 21258 | H39: 4% of total development cost before fee
C41: TOTAL DEVELOPMENT COST | D41: 395733600 | E41: 552701 | F41: 518.32 | G41: 1

Sheet Operating
B2: OPERATING PRO FORMA - 10 YEAR PROJECTION
B3: Year 1-2: Lease-up period. Year 3+: Stabilized operations. All values driven by Inputs tab.
C5: Line Item | D5: Year 1 | E5: Year 2 | F5: Year 3 | G5: Year 4 | H5: Year 5 | I5: Year 6 | J5: Year 7 | K5: Year 8 | L5: Year 9 | M5: Year 10 | N5: Year 11 | O5: $/Unit | P5: % of EGI
B6: REVENUE
C7: Market Rate Rental Income | D7: 6578640 | E7: 14329100 | F7: 16415249 | G7: 16825630 | H7: 17246271 | I7: 17677427 | J7: 18119363 | K7: 18572347 | L7: 19036656 | M7: 19512572 | N7: 20000387
C8: Affordable Rental Income | D8: 1166798 | E8: 2529036 | F8: 2883101 | G8: 2940763 | H8: 2999578 | I8: 3059569 | J8: 3120761 | K8: 3183176 | L8: 3246839 | M8: 3311776 | N8: 3378012
C9: Retail Income | D9: 48636 | E9: 94257 | F9: 101202 | G9: 103226 | H9: 105290 | I9: 107396 | J9: 109544 | K9: 111735 | L9: 113970 | M9: 116249 | N9: 118574
C10: Parking Income | D10: 149520 | E10: 324085 | F10: 369456 | G10: 376846 | H10: 384382 | I10: 392070 | J10: 399912 | K10: 407910 | L10: 416068 | M10: 424389 | N10: 432877
C11: Other Income | D11: 171840 | E11: 372463 | F11: 424608 | G11: 433100 | H11: 441762 | I11: 450597 | J11: 459609 | K11: 468802 | L11: 478178 | M11: 487741 | N11: 497496
C12: Gross Potential Revenue | D12: 8115434 | E12: 17648941 | F12: 20193616 | G12: 20679565 | H12: 21177283 | I12: 21687059 | J12: 22209189 | K12: 22743970 | L12: 23291711 | M12: 23852727 | N12: 24427346
C14: Less: Vacancy & Credit Loss | D14: -405772 | E14: -882447 | F14: -1009681 | G14: -1033978 | H14: -1058864 | I14: -1084353 | J14: -1110459 | K14: -1137198 | L14: -1164586 | M14: -1192636 | N14: -1221367
C15: Effective Gross Income | D15: 7709662 | E15: 16766494 | F15: 19183935 | G15: 19645587 | H15: 20118419 | I15: 20602706 | J15: 21098730 | K15: 21606772 | L15: 22127125 | M15: 22660091 | N15: 23205979
B17: OPERATING EXPENSES
C18: PILOT / Property Tax | D18: 1014429 | E18: 2206118 | F18: 2524202 | G18: 2584946 | H18: 2647160 | I18: 2710882 | J18: 2776149 | K18: 2842996 | L18: 2911464 | M18: 2981591 | N18: 3053418
C19: Insurance | D19: 1074000 | E19: 1106220 | F19: 1139407 | G19: 1173589 | H19: 1208796 | I19: 1245060 | J19: 1282412 | K19: 1320885 | L19: 1360511 | M19: 1401326 | N19: 1443366
C20: Management Fee | D20: 231290 | E20: 502995 | F20: 575518 | G20: 589368 | H20: 603553 | I20: 618081 | J20: 632962 | K20: 648203 | L20: 663814 | M20: 679803 | N20: 696179
C21: Repairs & Maintenance | D21: 716000 | E21: 737480 | F21: 759604 | G21: 782393 | H21: 805864 | I21: 830040 | J21: 854941 | K21: 880590 | L21: 907007 | M21: 934218 | N21: 962244
C22: Utilities | D22: 966600 | E22: 995598 | F22: 1025466 | G22: 1056230 | H22: 1087917 | I22: 1120554 | J22: 1154171 | K22: 1188796 | L22: 1224460 | M22: 1261194 | N22: 1299030
C23: General & Administrative | D23: 358000 | E23: 368740 | F23: 379802 | G23: 391196 | H23: 402932 | I23: 415020 | J23: 427471 | K23: 440295 | L23: 453504 | M23: 467109 | N23: 481122
C24: Marketing & Turnover | D24: 286400 | E24: 294992 | F24: 303842 | G24: 312957 | H24: 322346 | I24: 332016 | J24: 341977 | K24: 352236 | L24: 362803 | M24: 373687 | N24: 384898
C25: Payroll / On-Site Staff | D25: 1288800 | E25: 1327464 | F25: 1367288 | G25: 1408307 | H25: 1450556 | I25: 1494072 | J25: 1538895 | K25: 1585061 | L25: 1632613 | M25: 1681592 | N25: 1732039
C26: Replacement Reserves | D26: 214800 | E26: 221244 | F26: 227881 | G26: 234718 | H26: 241759 | I26: 249012 | J26: 256482 | K26: 264177 | L26: 272102 | M26: 280265 | N26: 288673
C27: TOTAL OPERATING EXPENSES | D27: 6150319 | E27: 7760851 | F27: 8303010 | G27: 8533704 | H27: 8770883 | I27: 9014737 | J27: 9265460 | K27: 9523239 | L27: 9788278 | M27: 10060785 | N27: 10340969
C29: NET OPERATING INCOME | D29: 1559343 | E29: 9005643 | F29: 10880925 | G29: 11111883 | H29: 11347536 | I29: 11587969 | J29: 11833270 | K29: 12083533 | L29: 12338847 | M29: 12599306 | N29: 12865010
C30: Yield on Cost | D30: 0.003118686 | E30: 0.018011286 | F30: 0.02176185 | G30: 0.022223766 | H30: 0.022695072 | I30: 0.023175938 | J30: 0.02366654 | K30: 0.024167066 | L30: 0.024677694 | M30: 0.025198612 | N30: 0.02573002
C31: Debt Service Coverage Ratio
C32: DSCR calculated on Waterfall tab based on permanent loan sizing

Sheet Aspire
B2: NJ ASPIRE TAX CREDIT ANALYSIS
B3: New Jersey Economic Recovery Act - Aspire Program (Enhanced Area: Newark)
B5: PROGRAM PARAMETERS
B6: Municipality | C6: Newark, NJ | E6: Enhanced Area municipality
B7: Location Tier | C7: Enhanced Area (QIT) | E7: Qualified Incentive Tract
B8: Maximum Credit % of Eligible Costs | C8: 0.6 | E8: Up to 60% for Enhanced Area
B9: Per-Project Credit Cap | C9: 90000000 | E9: $90M maximum
B10: Credit Duration | C10: 10 years | E10: Equal annual installments
B11: Minimum Eligible Project Cost | C11: 17500000 | E11: Pop > 200,000
B12: Affordable Housing Requirement | C12: 20% of units | E12: Mandatory for residential
B13: Green Building Standard | C13: LEED Silver or equiv. | E13: Mandatory compliance
B15: ELIGIBLE COST CALCULATION
B16: Total Development Cost | C16: 395733600 | E16: From Dev Budget tab
B17: Less: Land Acquisition (Excluded) | C17: -25000000 | E17: Land costs not eligible
B18: Eligible Project Costs (Before Cap) | C18: 370733600 | E18: Hard + soft + financing + fee
B19: Soft Cost Cap Check (20% of Total) | C19: 74146720 | E19: Soft costs cannot exceed 20%
B21: CREDIT CALCULATION
B22: Applied Credit Percentage | C22: 0.45 | E22: Conservative estimate (max 60%)
B23: Gross Credit Amount (Calculated) | C23: 166830120 | E23: =Eligible Costs x Credit %
B24: Per-Project Cap Applied | C24: 90000000 | E24: Cap if calculated exceeds $90M
B25: TOTAL ASPIRE CREDIT AWARD | C25: 90000000 | E25: Lesser of calculated or cap
B27: Annual Credit (10-Year) | C27: 9000000 | E27: =Total / 10 years
B28: Credit Sale / Transfer Rate | C28: 0.88 | E28: Market rate 85-92 cents
B29: NET ANNUAL PROCEEDS | C29: 7920000 | E29: After sale discount
B30: NET TOTAL PROCEEDS (10-Year) | C30: 79200000 | E30: Total monetizable value
B32: ANNUAL CREDIT SCHEDULE
B33: Year | C33: Annual Credit | D33: Net Proceeds
B34: Year 1 | C34: 9000000 | D34: 7920000
B35: Year 2 | C35: 9000000 | D35: 7920000
B36: Year 3 | C36: 9000000 | D36: 7920000
B37: Year 4 | C37: 9000000 | D37: 7920000
B38: Year 5 | C38: 9000000 | D38: 7920000
B39: Year 6 | C39: 9000000 | D39: 7920000
B40: Year 7 | C40: 9000000 | D40: 7920000
B41: Year 8 | C41: 9000000 | D41: 7920000
B42: Year 9 | C42: 9000000 | D42: 7920000
B43: Year 10 | C43: 9000000 | D43: 7920000
B44: TOTAL | C44: 90000000 | D44: 79200000
B46: ASPIRE COMPLIANCE REQUIREMENTS
B47: 20% affordable housing set-aside (30-year deed restriction)
...

Sheet Waterfall
B2: SPONSOR EQUITY WATERFALL ANALYSIS
B3: 50/50 GP/LP equity split (adjustable on Inputs tab). Waterfall with preferred return and tiered promote.
B5: CAPITAL STRUCTURE
B6: Total Development Cost | C6: 395733600
B8: Stabilized NOI (Year 3) | C8: 10880925 | E8: From Operating Pro Forma
B9: Going-In Cap Rate | C9: 0.05
B10: Implied Property Value | C10: 217618500 | E10: =NOI / Cap Rate
B12: Permanent Loan Amount | C12: 120989803 | E12: Constrained by LTV & DSCR
B13: Loan-to-Value | C13: 0.55597205
B14: Annual Debt Service | C14: 8704740
B15: DSCR | C15: 1.25 | E15: Min 1.25x required
B17: TOTAL EQUITY REQUIRED | C17: 274743797 | E17: =TDC - Perm Loan
B18: Less: Aspire Credit Proceeds | C18: -79200000 | E18: Net monetized credits
B19: NET EQUITY REQUIRED | C19: 195543797 | E19: After Aspire offset
B21: Sponsor (GP) Equity | C21: 97771898 | E21: 50% share
B22: LP Equity | C22: 97771898 | E22: 50% share
B24: WATERFALL STRUCTURE
B25: Tier 0: Return of Capital | C25: 100% pro rata | E25: Return all invested equity first
B26: Tier 1: Preferred Return (8%) | C26: 100% to equity holders pro rata | E26: Cumulative, non-compounding
B27: Tier 2: Catch-Up to 12% IRR | C27: 80% LP / 20% GP | E27: GP promote begins
B28: Tier 3: Above 12% to 18% IRR | C28: 70% LP / 30% GP | E28: Increased GP promote
B29: Tier 4: Above 18% IRR | C29: 60% LP / 40% GP | E29: Maximum GP promote
B31: ANNUAL CASH FLOW PROJECTION
C33: Year 0 | D33: Year 1 | E33: Year 2 | F33: Year 3 | G33: Year 4 | H33: Year 5 | I33: Year 6 | J33: Year 7 | K33: Year 8 | L33: Year 9 | M33: Year 10 | N33: Year 10 (Sale)
B34: Net Operating Income | C34: 0 | D34: 1559343 | E34: 9005643 | F34: 10880925 | G34: 11111883 | H34: 11347536 | I34: 11587969 | J34: 11833270 | K34: 12083533 | L34: 12338847 | M34: 12599306 | N34: 12865010
B35: Less: Debt Service | C35: 0 | D35: -8704740 | E35: -8704740 | F35: -8704740 | G35: -8704740 | H35: -8704740 | I35: -8704740 | J35: -8704740 | K35: -8704740 | L35: -8704740 | M35: -8704740 | N35: -8704740
B36: Aspire Credit Proceeds | C36: 0 | D36: 7920000 | E36: 7920000 | F36: 7920000 | G36: 7920000 | H36: 7920000 | I36: 7920000 | J36: 7920000 | K36: 7920000 | L36: 7920000 | M36: 7920000 | N36: 0
B37: LEVERED CASH FLOW | C37: -195543797 | D37: 774603 | E37: 8220903 | F37: 10096185 | G37: 10327143 | H37: 10562796 | I37: 10803229 | J37: 11048530 | K37: 11298793 | L37: 11554107 | M37: 11814566 | N37: 4160270
B39: EXIT / DISPOSITION (Year 10)
B40: Exit NOI (Year 11) | C40: 12865010
B41: Exit Cap Rate | C41: 0.0525
B42: Gross Sale Price | C42: 245047810
B43: Less: Disposition Costs (2%) | C43: -4900956
B44: Less: NJ Transfer Tax (4.1%) | C44: -10046960
B45: Less: Loan Payoff (Est. Balance) | C45: -102841333
B46: NET SALE PROCEEDS TO EQUITY | C46: 127258561
B48: RETURN METRICS
B49: Unlevered IRR | C49: 0.0086021334
B50: Levered IRR (Project) | C50: 0.017394246
B51: Equity Multiple | C51: 1.1655685
...

Sheet Tax Implications
B2: TAX IMPLICATIONS & DEPRECIATION
B3: Federal and NJ state tax considerations for real estate investment
B5: DEPRECIATION SCHEDULE
B6: Total Development Cost | C6: 395733600
B7: Less: Land (Non-Depreciable) | C7: -25000000
B8: Depreciable Basis | C8: 370733600
B10: Residential Portion (85%) | C10: 315123560 | E10: 27.5-year straight line
B11: Commercial Portion (15%) | C11: 55610040 | E11: 39-year straight line
B13: Annual Residential Depreciation | C13: 11459039 | E13: =Res Basis / 27.5 yrs
B14: Annual Commercial Depreciation | C14: 1425898 | E14: =Comm Basis / 39 yrs
B15: Total Annual Depreciation | C15: 12884937
B17: NEWARK PILOT PROGRAM
B18: PILOT Structure | C18: % of Gross Revenue | E18: Payment In Lieu of Taxes
B19: PILOT Rate | C19: 0.125 | E19: 12.5% of gross revenue (adjustable)
B20: PILOT Duration | C20: 30 years | E20: Standard for new construction
B21: Conventional Tax Rate (Comparison) | C21: 0.04 | E21: $4.00 per $100 assessed value
B23: Estimated Annual PILOT (Stabilized) | E23: See Operating Pro Forma
B24: Estimated Conventional Tax | E24: If no PILOT abatement
B25: Annual Tax Savings from PILOT | E25: Significant NOI benefit
B27: INTEREST DEDUCTIBILITY
B28: Annual Mortgage Interest (Est. Year 1) | C28: 7259388 | E28: Approximately 6% x loan balance (declining over time)
B29: Interest expense is deductible against taxable income, reducing tax liability
B31: DISPOSITION TAX ESTIMATES
B32: NJ Realty Transfer Fee | C32: ~4.1% | E32: Graduated fee + mansion tax for $200M+ sale
B33: Federal Capital Gains Rate | C33: 20% | E33: Long-term capital gains (>1 year hold)
B34: NJ State Income Tax Rate | C34: 10.75% | E34: Top marginal rate
B35: Depreciation Recapture Rate | C35: 25% | E35: Federal recapture on accumulated depreciation
B36: Net Investment Income Tax | C36: 3.8% | E36: Additional Medicare surtax
B37: 1031 Exchange Eligibility | C37: Available | E37: Tax deferral if reinvested in like-kind property
B38: Opportunity Zone Benefits | C38: To Be Evaluated | E38: If applicable to Newark OZ designation

Sheet Sensitivity
B2: SENSITIVITY ANALYSIS
B3: Impact of key variable changes on project returns. All tables are independent scenarios.
B5: YIELD ON COST: Rent Change vs. Construction Cost Change
B6: Values show Stabilized Yield on Cost under each scenario
B7: Rent \ Cost | C7: -10% | D7: -5% | E7: Base | F7: +5% | G7: +10% | H7: +15%
B8: -10% | C8: 0.02749558 | D8: 0.026048445 | E8: 0.024746022 | F8: 0.02356764 | G8: 0.022496384 | H8: 0.02151828
B9: -5% | C9: 0.029023113 | D9: 0.02749558 | E9: 0.026120801 | F9: 0.024876954 | G9: 0.023746183 | H9: 0.02271374
B10: Base | C10: 0.030550645 | D10: 0.028942716 | E10: 0.02749558 | F10: 0.026186267 | G10: 0.024995982 | H10: 0.0239092
B11: +5% | C11: 0.032078177 | D11: 0.030389852 | E11: 0.028870359 | F11: 0.02749558 | G11: 0.026245781 | H11: 0.02510466
B12: +10% | C12: 0.033605709 | D12: 0.031836988 | E12: 0.030245138 | F12: 0.028804894 | G12: 0.02749558 | H12: 0.02630012
B13: +15% | C13: 0.035133242 | D13: 0.033284124 | E13: 0.031619917 | F13: 0.030114207 | G13: 0.028745379 | H13: 0.02749558
B16: PROPERTY VALUE ($M): Exit Cap Rate vs. NOI Change
B17: Values show estimated property value in millions
B18: Cap \ NOI | C18: -10% | D18: -5% | E18: Base | F18: +5% | G18: +10%
B19: 0.04 | C19: 244.82081 | D19: 258.42197 | E19: 272.02312 | F19: 285.62428 | G19: 299.22544
B20: 0.0425 | C20: 230.41959 | D20: 243.22068 | E20: 256.02176 | F20: 268.82285 | G20: 281.62394
B21: 0.045 | C21: 217.6185 | D21: 229.70842 | E21: 241.79833 | F21: 253.88825 | G21: 265.97817
B22: 0.0475 | C22: 206.16489 | D22: 217.6185 | E22: 229.07211 | F22: 240.52571 | G22: 251.97932
B23: 0.05 | C23: 195.85665 | D23: 206.73757 | E23: 217.6185 | F23: 228.49943 | G23: 239.38035
B24: 0.0525 | C24: 186.53014 | D24: 196.89293 | E24: 207.25571 | F24: 217.6185 | G24: 227.98129
B25: 0.055 | C25: 178.0515 | D25: 187.94325 | E25: 197.835 | F25: 207.72675 | G25: 217.6185
B28: NOI SENSITIVITY: Vacancy Rate vs. OpEx Growth
B29: Vac \ OpEx | C29: -5% | D29: Base | E29: +5% | F29: +10% | G29: +15%
B30: 3% | C30: 11542485 | D30: 11316162 | E30: 11089839 | F30: 10863516 | G30: 10637192
B31: 5% | C31: 11098544 | D31: 10880925 | E31: 10663306 | F31: 10445688 | G31: 10228070
B32: 7% | C32: 10654602 | D32: 10445688 | E32: 10236774 | F32: 10027860 | G32: 9818947
B33: 10% | C33: 9988689 | D33: 9792832 | E33: 9596976 | F33: 9401119 | G33: 9205263
B34: 12% | C34: 9544747 | D34: 9357596 | E34: 9170444 | F34: 8983292 | G34: 8796140
B35: 15% | C35: 8878835 | D35: 8704740 | E35: 8530645 | F35: 8356550 | G35: 8182456
B38: DEBT SERVICE: Permanent Loan Rate Sensitivity
B39: Impact on annual debt service and DSCR at various interest rates
B40: Perm Rate | C40: Loan Amount | D40: Annual DS | E40: DSCR | F40: Monthly DS | G40: Excess CF (over DS)
B41: 0.045 | C41: 143164798 | D41: 8704740 | E41: 1.25 | F41: 725395 | G41: 2176185
B42: 0.05 | C42: 135127754 | D42: 8704740 | E42: 1.25 | F42: 725395 | G42: 2176185
B43: 0.055 | C43: 127757846 | D43: 8704740 | E43: 1.25 | F43: 725395 | G43: 2176185
B44: 0.06 | C44: 120989803 | D44: 8704740 | E44: 1.25 | F44: 725395 | G44: 2176185
B45: 0.065 | C45: 114765337 | D45: 8704740 | E45: 1.25 | F45: 725395 | G45: 2176185
B46: 0.07 | C46: 109032358 | D46: 8704740 | E46: 1.25 | F46: 725395 | G46: 2176185
B47: 0.075 | C47: 103744272 | D47: 8704740 | E47: 1.25 | F47: 725395 | G47: 2176185
B48: 0.08 | C48: 98859365 | D48: 8704740 | E48: 1.25 | F48: 725395 | G48: 2176185
...
